<?xml version="1.0"?>
<robot name="murphy" xmlns:xacro="http://www.ros.org/wiki/xacro">
  <ros2_control name="MurphySystem" type="system">
  <hardware>
    <plugin>gz_ros2_control/GazeboSimSystem</plugin>
  </hardware>

  <joint name="front_left_wheel_joint">
    <command_interface name="velocity"/>
    <state_interface name="position"/>
    <state_interface name="velocity"/>
  </joint>

  <joint name="rear_left_wheel_joint">
    <command_interface name="velocity"/>
    <state_interface name="position"/>
    <state_interface name="velocity"/>
  </joint>

  <joint name="front_right_wheel_joint">
    <command_interface name="velocity"/>
    <state_interface name="position"/>
    <state_interface name="velocity"/>
  </joint>

  <joint name="rear_right_wheel_joint">
    <command_interface name="velocity"/>
    <state_interface name="position"/>
    <state_interface name="velocity"/>
  </joint>
</ros2_control>

  <xacro:property name="pi" value="3.14159265359"/>
  <xacro:property name="wheel_radius" value="0.07"/>
  <xacro:property name="base_height" value="0.1"/>

  <link name="base_link">
    <visual>
      <geometry>
        <box size="0.4 0.3 ${base_height}"/>
      </geometry>
      <origin xyz="0 0 ${wheel_radius}"/>
      <material name="blue">
        <color rgba="0.2 0.2 1.0 1.0"/>
      </material>
    </visual>
    <collision>
      <geometry>
        <box size="0.4 0.3 ${base_height}"/>
      </geometry>
      <origin xyz="0 0 ${wheel_radius}"/>
    </collision>
    <inertial>
      <mass value="8.0"/>
      <origin xyz="0 0 ${wheel_radius}"/>
      <inertia ixx="0.2" iyy="0.2" izz="0.2"
               ixy="0" ixz="0" iyz="0"/>
    </inertial>
  </link>
  
  <link name="lidar_link">
    <visual>
      <geometry>
        <cylinder radius="0.04" length="0.05"/>
      </geometry>
      <origin xyz="0 0 0"/>
      <material name="gray">
        <color rgba="0.6 0.6 0.6 1.0"/>
      </material>
    </visual>
  </link>

  <joint name="lidar_joint" type="fixed">
    <parent link="base_link"/>
    <child link="lidar_link"/>
    <origin xyz="0.15 0 0.15"/>
  </joint>

  <link name="imu_link">
    <visual>
      <geometry>
        <box size="0.03 0.03 0.02"/>
      </geometry>
      <material name="orange">
        <color rgba="1 0.5 0 1"/>
      </material>
    </visual>
  </link>

  <joint name="imu_joint" type="fixed">
    <parent link="base_link"/>
    <child link="imu_link"/>
    <origin xyz="0 0 0.15"/>
  </joint>

  <xacro:macro name="wheel" params="name x y">

    <link name="${name}">
      <visual>
        <geometry>
          <cylinder radius="${wheel_radius}" length="0.04"/>
        </geometry>
        <origin rpy="${pi/2} 0 0"/>
        <material name="black">
          <color rgba="0.2 0.2 0.2 1.0"/>
        </material>
      </visual>

      <collision>
        <geometry>
          <cylinder radius="${wheel_radius}" length="0.04"/>
        </geometry>
        <origin rpy="${pi/2} 0 0"/>
      </collision>

      <inertial>
        <mass value="1.0"/>
        <origin xyz="0 0 0"/>
        <inertia ixx="${0.01}" iyy="${0.01}" izz="${0.005}"
                 ixy="0" ixz="0" iyz="0"/>
      </inertial>
    </link>

    <joint name="${name}_joint" type="continuous">
      <parent link="base_link"/>
      <child link="${name}"/>
      <origin xyz="${x} ${y} ${wheel_radius}" rpy="0 0 0"/>
      <axis xyz="0 1 0"/>
    </joint>

  </xacro:macro>

  <xacro:wheel name="front_left_wheel"  x="0.15"  y="0.15"/>
  <xacro:wheel name="front_right_wheel" x="0.15"  y="-0.15"/>
  <xacro:wheel name="rear_left_wheel"   x="-0.15" y="0.15"/>
  <xacro:wheel name="rear_right_wheel"  x="-0.15" y="-0.15"/>

<gazebo reference="lidar_link">
  <sensor name="lidar" type="gpu_lidar">
    <update_rate>10</update_rate>
    <topic>scan</topic>
    <lidar>
      <scan>
        <horizontal>
          <samples>360</samples>
          <min_angle>-3.14</min_angle>
          <max_angle>3.14</max_angle>
        </horizontal>
      </scan>
      <range>
        <min>0.1</min>
        <max>10.0</max>
      </range>
    </lidar>
  </sensor>
</gazebo>

<gazebo reference="imu_link">
  <sensor name="imu_sensor" type="imu">
    <update_rate>100</update_rate>
    <topic>imu</topic>
    <always_on>true</always_on>
  </sensor>
</gazebo>
<gazebo>
  <plugin filename="libgz_ros2_control-system.so"
          name="gz_ros2_control::GazeboSimROS2ControlPlugin">

    <parameters>$(find murphy_description)/config/controllers.yaml</parameters>

  </plugin>
</gazebo>


</robot>